C:\Users\elinor.g\AppData\Local\Programs\Python\Python36\python.exe C:/Users/elinor.g/Desktop/pd/ddqn.py
2019-11-16 22:35:26.847829: I tensorflow/core/platform/cpu_feature_guard.cc:142] Your CPU supports instructions that this TensorFlow binary was not compiled to use: AVX2
Model: "sequential"
_________________________________________________________________
Layer (type)                 Output Shape              Param #   
=================================================================
conv2d (Conv2D)              (None, 30, 30, 32)        896       
_________________________________________________________________
max_pooling2d (MaxPooling2D) (None, 15, 15, 32)        0         
_________________________________________________________________
conv2d_1 (Conv2D)            (None, 13, 13, 64)        18496     
_________________________________________________________________
max_pooling2d_1 (MaxPooling2 (None, 6, 6, 64)          0         
_________________________________________________________________
conv2d_2 (Conv2D)            (None, 4, 4, 64)          36928     
_________________________________________________________________
flatten (Flatten)            (None, 1024)              0         
_________________________________________________________________
dense (Dense)                (None, 64)                65600     
_________________________________________________________________
dense_1 (Dense)              (None, 10)                650       
=================================================================
Total params: 122,570
Trainable params: 122,570
Non-trainable params: 0
_________________________________________________________________
Model: "sequential_1"
_________________________________________________________________
Layer (type)                 Output Shape              Param #   
=================================================================
conv2d_3 (Conv2D)            (None, 30, 30, 32)        896       
_________________________________________________________________
max_pooling2d_2 (MaxPooling2 (None, 15, 15, 32)        0         
_________________________________________________________________
conv2d_4 (Conv2D)            (None, 13, 13, 64)        18496     
_________________________________________________________________
max_pooling2d_3 (MaxPooling2 (None, 6, 6, 64)          0         
_________________________________________________________________
conv2d_5 (Conv2D)            (None, 4, 4, 64)          36928     
_________________________________________________________________
flatten_1 (Flatten)          (None, 1024)              0         
_________________________________________________________________
dense_2 (Dense)              (None, 64)                65600     
_________________________________________________________________
dense_3 (Dense)              (None, 10)                650       
=================================================================
Total params: 122,570
Trainable params: 122,570
Non-trainable params: 0
_________________________________________________________________
Train on 1 samples
Epoch 1/10
Traceback (most recent call last):
  File "C:/Users/elinor.g/Desktop/pd/ddqn.py", line 163, in <module>
    exec_process()
  File "C:/Users/elinor.g/Desktop/pd/ddqn.py", line 83, in exec_process
    history = network.fit(state, epochs=10, batch_size=10)
  File "C:\Users\elinor.g\AppData\Local\Programs\Python\Python36\lib\site-packages\tensorflow_core\python\keras\engine\training.py", line 728, in fit
    use_multiprocessing=use_multiprocessing)

1/1 [==============================] - 0s 79ms/sample
  File "C:\Users\elinor.g\AppData\Local\Programs\Python\Python36\lib\site-packages\tensorflow_core\python\keras\engine\training_v2.py", line 324, in fit
    total_epochs=epochs)
  File "C:\Users\elinor.g\AppData\Local\Programs\Python\Python36\lib\site-packages\tensorflow_core\python\keras\engine\training_v2.py", line 123, in run_one_epoch
    batch_outs = execution_function(iterator)
  File "C:\Users\elinor.g\AppData\Local\Programs\Python\Python36\lib\site-packages\tensorflow_core\python\keras\engine\training_v2_utils.py", line 86, in execution_function
    distributed_function(input_fn))
  File "C:\Users\elinor.g\AppData\Local\Programs\Python\Python36\lib\site-packages\tensorflow_core\python\eager\def_function.py", line 457, in __call__
    result = self._call(*args, **kwds)
  File "C:\Users\elinor.g\AppData\Local\Programs\Python\Python36\lib\site-packages\tensorflow_core\python\eager\def_function.py", line 503, in _call
    self._initialize(args, kwds, add_initializers_to=initializer_map)
  File "C:\Users\elinor.g\AppData\Local\Programs\Python\Python36\lib\site-packages\tensorflow_core\python\eager\def_function.py", line 408, in _initialize
    *args, **kwds))
  File "C:\Users\elinor.g\AppData\Local\Programs\Python\Python36\lib\site-packages\tensorflow_core\python\eager\function.py", line 1848, in _get_concrete_function_internal_garbage_collected
    graph_function, _, _ = self._maybe_define_function(args, kwargs)
  File "C:\Users\elinor.g\AppData\Local\Programs\Python\Python36\lib\site-packages\tensorflow_core\python\eager\function.py", line 2150, in _maybe_define_function
    graph_function = self._create_graph_function(args, kwargs)
  File "C:\Users\elinor.g\AppData\Local\Programs\Python\Python36\lib\site-packages\tensorflow_core\python\eager\function.py", line 2041, in _create_graph_function
    capture_by_value=self._capture_by_value),
  File "C:\Users\elinor.g\AppData\Local\Programs\Python\Python36\lib\site-packages\tensorflow_core\python\framework\func_graph.py", line 915, in func_graph_from_py_func
    func_outputs = python_func(*func_args, **func_kwargs)
  File "C:\Users\elinor.g\AppData\Local\Programs\Python\Python36\lib\site-packages\tensorflow_core\python\eager\def_function.py", line 358, in wrapped_fn
    return weak_wrapped_fn().__wrapped__(*args, **kwds)
  File "C:\Users\elinor.g\AppData\Local\Programs\Python\Python36\lib\site-packages\tensorflow_core\python\keras\engine\training_v2_utils.py", line 73, in distributed_function
    per_replica_function, args=(model, x, y, sample_weights))
  File "C:\Users\elinor.g\AppData\Local\Programs\Python\Python36\lib\site-packages\tensorflow_core\python\distribute\distribute_lib.py", line 760, in experimental_run_v2
    return self._extended.call_for_each_replica(fn, args=args, kwargs=kwargs)
  File "C:\Users\elinor.g\AppData\Local\Programs\Python\Python36\lib\site-packages\tensorflow_core\python\distribute\distribute_lib.py", line 1787, in call_for_each_replica
    return self._call_for_each_replica(fn, args, kwargs)
  File "C:\Users\elinor.g\AppData\Local\Programs\Python\Python36\lib\site-packages\tensorflow_core\python\distribute\distribute_lib.py", line 2132, in _call_for_each_replica
    return fn(*args, **kwargs)
  File "C:\Users\elinor.g\AppData\Local\Programs\Python\Python36\lib\site-packages\tensorflow_core\python\autograph\impl\api.py", line 292, in wrapper
    return func(*args, **kwargs)
  File "C:\Users\elinor.g\AppData\Local\Programs\Python\Python36\lib\site-packages\tensorflow_core\python\keras\engine\training_v2_utils.py", line 264, in train_on_batch
    output_loss_metrics=model._output_loss_metrics)
  File "C:\Users\elinor.g\AppData\Local\Programs\Python\Python36\lib\site-packages\tensorflow_core\python\keras\engine\training_eager.py", line 311, in train_on_batch
    output_loss_metrics=output_loss_metrics))
  File "C:\Users\elinor.g\AppData\Local\Programs\Python\Python36\lib\site-packages\tensorflow_core\python\keras\engine\training_eager.py", line 252, in _process_single_batch
    training=training))
  File "C:\Users\elinor.g\AppData\Local\Programs\Python\Python36\lib\site-packages\tensorflow_core\python\keras\engine\training_eager.py", line 166, in _model_loss
    per_sample_losses = loss_fn.call(targets[i], outs[i])
IndexError: list index out of range

Process finished with exit code 1
